[2024-11-23T10:45:46.235+0000] {local_task_job_runner.py:123} INFO - ::group::Pre task execution logs
[2024-11-23T10:45:46.260+0000] {taskinstance.py:2613} INFO - Dependencies all met for dep_context=non-requeueable deps ti=<TaskInstance: data_processing_dag.process_data manual__2024-11-23T10:45:27.644336+00:00 [queued]>
[2024-11-23T10:45:46.271+0000] {taskinstance.py:2613} INFO - Dependencies all met for dep_context=requeueable deps ti=<TaskInstance: data_processing_dag.process_data manual__2024-11-23T10:45:27.644336+00:00 [queued]>
[2024-11-23T10:45:46.272+0000] {taskinstance.py:2866} INFO - Starting attempt 1 of 1
[2024-11-23T10:45:46.494+0000] {taskinstance.py:2889} INFO - Executing <Task(PythonOperator): process_data> on 2024-11-23 10:45:27.644336+00:00
[2024-11-23T10:45:46.506+0000] {warnings.py:112} WARNING - /home/***/.local/lib/python3.12/site-packages/***/task/task_runner/standard_task_runner.py:70: DeprecationWarning: This process (pid=121) is multi-threaded, use of fork() may lead to deadlocks in the child.
  pid = os.fork()

[2024-11-23T10:45:46.508+0000] {standard_task_runner.py:72} INFO - Started process 137 to run task
[2024-11-23T10:45:46.508+0000] {standard_task_runner.py:104} INFO - Running: ['***', 'tasks', 'run', 'data_processing_dag', 'process_data', 'manual__2024-11-23T10:45:27.644336+00:00', '--job-id', '13', '--raw', '--subdir', 'DAGS_FOLDER/data_processing_dag.py', '--cfg-path', '/tmp/tmptcsuld48']
[2024-11-23T10:45:46.510+0000] {standard_task_runner.py:105} INFO - Job 13: Subtask process_data
[2024-11-23T10:45:46.795+0000] {task_command.py:467} INFO - Running <TaskInstance: data_processing_dag.process_data manual__2024-11-23T10:45:27.644336+00:00 [running]> on host 8f56532c35d7
[2024-11-23T10:45:47.470+0000] {taskinstance.py:3132} INFO - Exporting env vars: AIRFLOW_CTX_DAG_OWNER='***' AIRFLOW_CTX_DAG_ID='data_processing_dag' AIRFLOW_CTX_TASK_ID='process_data' AIRFLOW_CTX_EXECUTION_DATE='2024-11-23T10:45:27.644336+00:00' AIRFLOW_CTX_TRY_NUMBER='1' AIRFLOW_CTX_DAG_RUN_ID='manual__2024-11-23T10:45:27.644336+00:00'
[2024-11-23T10:45:47.472+0000] {logging_mixin.py:190} INFO - Task instance is in running state
[2024-11-23T10:45:47.473+0000] {logging_mixin.py:190} INFO -  Previous state of the Task instance: queued
[2024-11-23T10:45:47.474+0000] {logging_mixin.py:190} INFO - Current task name:process_data state:running start_date:2024-11-23 10:45:46.261606+00:00
[2024-11-23T10:45:47.474+0000] {logging_mixin.py:190} INFO - Dag name:data_processing_dag and current dag run status:running
[2024-11-23T10:45:47.475+0000] {taskinstance.py:731} INFO - ::endgroup::
[2024-11-23T10:45:47.482+0000] {warnings.py:112} WARNING - /home/***/.local/lib/python3.12/site-packages/gdown/parse_url.py:48: UserWarning: You specified a Google Drive link that is not the correct link to download a file. You might want to try `--fuzzy` option or the following url: https://drive.google.com/uc?id=None
  warnings.warn(

[2024-11-23T10:45:48.757+0000] {logging_mixin.py:190} WARNING - Downloading...
[2024-11-23T10:45:48.757+0000] {logging_mixin.py:190} WARNING - From: https://drive.google.com/drive/folders/1jF_BovhtYn67ctVjByaqFY6NyLtF0CH5?usp=drive_link
[2024-11-23T10:45:48.758+0000] {logging_mixin.py:190} WARNING - To: /tmp/ASIdataset.zip
[2024-11-23T10:45:48.762+0000] {logging_mixin.py:190} WARNING - 0.00B [00:00, ?B/s]
[2024-11-23T10:45:48.813+0000] {logging_mixin.py:190} WARNING - 1.19MB [00:00, 23.8MB/s]
[2024-11-23T10:45:48.833+0000] {taskinstance.py:3311} ERROR - Task failed with exception
Traceback (most recent call last):
  File "/home/airflow/.local/lib/python3.12/site-packages/airflow/models/taskinstance.py", line 767, in _execute_task
    result = _execute_callable(context=context, **execute_callable_kwargs)
             ^^^^^^^^^^^^^^^^^^^^^^^^^^^^^^^^^^^^^^^^^^^^^^^^^^^^^^^^^^^^^
  File "/home/airflow/.local/lib/python3.12/site-packages/airflow/models/taskinstance.py", line 733, in _execute_callable
    return ExecutionCallableRunner(
           ^^^^^^^^^^^^^^^^^^^^^^^^
  File "/home/airflow/.local/lib/python3.12/site-packages/airflow/utils/operator_helpers.py", line 252, in run
    return self.func(*args, **kwargs)
           ^^^^^^^^^^^^^^^^^^^^^^^^^^
  File "/home/airflow/.local/lib/python3.12/site-packages/airflow/models/baseoperator.py", line 417, in wrapper
    return func(self, *args, **kwargs)
           ^^^^^^^^^^^^^^^^^^^^^^^^^^^
  File "/home/airflow/.local/lib/python3.12/site-packages/airflow/operators/python.py", line 238, in execute
    return_value = self.execute_callable()
                   ^^^^^^^^^^^^^^^^^^^^^^^
  File "/home/airflow/.local/lib/python3.12/site-packages/airflow/operators/python.py", line 256, in execute_callable
    return runner.run(*self.op_args, **self.op_kwargs)
           ^^^^^^^^^^^^^^^^^^^^^^^^^^^^^^^^^^^^^^^^^^^
  File "/home/airflow/.local/lib/python3.12/site-packages/airflow/utils/operator_helpers.py", line 252, in run
    return self.func(*args, **kwargs)
           ^^^^^^^^^^^^^^^^^^^^^^^^^^
  File "/opt/airflow/dags/data_processing_dag.py", line 23, in process_data
    with zipfile.ZipFile(dataset_zip_path, 'r') as zip_ref:
         ^^^^^^^^^^^^^^^^^^^^^^^^^^^^^^^^^^^^^^
  File "/usr/local/lib/python3.12/zipfile/__init__.py", line 1349, in __init__
    self._RealGetContents()
  File "/usr/local/lib/python3.12/zipfile/__init__.py", line 1416, in _RealGetContents
    raise BadZipFile("File is not a zip file")
zipfile.BadZipFile: File is not a zip file
[2024-11-23T10:45:51.186+0000] {logging_mixin.py:190} INFO - Task instance in failure state
[2024-11-23T10:45:51.187+0000] {logging_mixin.py:190} INFO - Task start:2024-11-23 10:45:46.261606+00:00 end:2024-11-23 10:45:51.185223+00:00 duration:4.923617
[2024-11-23T10:45:51.188+0000] {logging_mixin.py:190} INFO - Task:<Task(PythonOperator): process_data> dag:<DAG: data_processing_dag> dagrun:<DagRun data_processing_dag @ 2024-11-23 10:45:27.644336+00:00: manual__2024-11-23T10:45:27.644336+00:00, state:running, queued_at: 2024-11-23 10:45:27.662210+00:00. externally triggered: True>
[2024-11-23T10:45:51.189+0000] {logging_mixin.py:190} INFO - Failure caused by File is not a zip file
[2024-11-23T10:45:51.190+0000] {taskinstance.py:1225} INFO - Marking task as FAILED. dag_id=data_processing_dag, task_id=process_data, run_id=manual__2024-11-23T10:45:27.644336+00:00, execution_date=20241123T104527, start_date=20241123T104546, end_date=20241123T104551
[2024-11-23T10:45:52.815+0000] {taskinstance.py:340} INFO - ::group::Post task execution logs
[2024-11-23T10:45:52.817+0000] {standard_task_runner.py:124} ERROR - Failed to execute job 13 for task process_data (File is not a zip file; 137)
Traceback (most recent call last):
  File "/home/airflow/.local/lib/python3.12/site-packages/airflow/task/task_runner/standard_task_runner.py", line 117, in _start_by_fork
    ret = args.func(args, dag=self.dag)
          ^^^^^^^^^^^^^^^^^^^^^^^^^^^^^
  File "/home/airflow/.local/lib/python3.12/site-packages/airflow/cli/cli_config.py", line 49, in command
    return func(*args, **kwargs)
           ^^^^^^^^^^^^^^^^^^^^^
  File "/home/airflow/.local/lib/python3.12/site-packages/airflow/utils/cli.py", line 116, in wrapper
    return f(*args, **kwargs)
           ^^^^^^^^^^^^^^^^^^
  File "/home/airflow/.local/lib/python3.12/site-packages/airflow/cli/commands/task_command.py", line 483, in task_run
    task_return_code = _run_task_by_selected_method(args, _dag, ti)
                       ^^^^^^^^^^^^^^^^^^^^^^^^^^^^^^^^^^^^^^^^^^^^
  File "/home/airflow/.local/lib/python3.12/site-packages/airflow/cli/commands/task_command.py", line 256, in _run_task_by_selected_method
    return _run_raw_task(args, ti)
           ^^^^^^^^^^^^^^^^^^^^^^^
  File "/home/airflow/.local/lib/python3.12/site-packages/airflow/cli/commands/task_command.py", line 341, in _run_raw_task
    return ti._run_raw_task(
           ^^^^^^^^^^^^^^^^^
  File "/home/airflow/.local/lib/python3.12/site-packages/airflow/utils/session.py", line 97, in wrapper
    return func(*args, session=session, **kwargs)
           ^^^^^^^^^^^^^^^^^^^^^^^^^^^^^^^^^^^^^^
  File "/home/airflow/.local/lib/python3.12/site-packages/airflow/models/taskinstance.py", line 3005, in _run_raw_task
    return _run_raw_task(
           ^^^^^^^^^^^^^^
  File "/home/airflow/.local/lib/python3.12/site-packages/airflow/models/taskinstance.py", line 273, in _run_raw_task
    TaskInstance._execute_task_with_callbacks(
  File "/home/airflow/.local/lib/python3.12/site-packages/airflow/models/taskinstance.py", line 3159, in _execute_task_with_callbacks
    result = self._execute_task(context, task_orig)
             ^^^^^^^^^^^^^^^^^^^^^^^^^^^^^^^^^^^^^^
  File "/home/airflow/.local/lib/python3.12/site-packages/airflow/models/taskinstance.py", line 3183, in _execute_task
    return _execute_task(self, context, task_orig)
           ^^^^^^^^^^^^^^^^^^^^^^^^^^^^^^^^^^^^^^^
  File "/home/airflow/.local/lib/python3.12/site-packages/airflow/models/taskinstance.py", line 767, in _execute_task
    result = _execute_callable(context=context, **execute_callable_kwargs)
             ^^^^^^^^^^^^^^^^^^^^^^^^^^^^^^^^^^^^^^^^^^^^^^^^^^^^^^^^^^^^^
  File "/home/airflow/.local/lib/python3.12/site-packages/airflow/models/taskinstance.py", line 733, in _execute_callable
    return ExecutionCallableRunner(
           ^^^^^^^^^^^^^^^^^^^^^^^^
  File "/home/airflow/.local/lib/python3.12/site-packages/airflow/utils/operator_helpers.py", line 252, in run
    return self.func(*args, **kwargs)
           ^^^^^^^^^^^^^^^^^^^^^^^^^^
  File "/home/airflow/.local/lib/python3.12/site-packages/airflow/models/baseoperator.py", line 417, in wrapper
    return func(self, *args, **kwargs)
           ^^^^^^^^^^^^^^^^^^^^^^^^^^^
  File "/home/airflow/.local/lib/python3.12/site-packages/airflow/operators/python.py", line 238, in execute
    return_value = self.execute_callable()
                   ^^^^^^^^^^^^^^^^^^^^^^^
  File "/home/airflow/.local/lib/python3.12/site-packages/airflow/operators/python.py", line 256, in execute_callable
    return runner.run(*self.op_args, **self.op_kwargs)
           ^^^^^^^^^^^^^^^^^^^^^^^^^^^^^^^^^^^^^^^^^^^
  File "/home/airflow/.local/lib/python3.12/site-packages/airflow/utils/operator_helpers.py", line 252, in run
    return self.func(*args, **kwargs)
           ^^^^^^^^^^^^^^^^^^^^^^^^^^
  File "/opt/airflow/dags/data_processing_dag.py", line 23, in process_data
    with zipfile.ZipFile(dataset_zip_path, 'r') as zip_ref:
         ^^^^^^^^^^^^^^^^^^^^^^^^^^^^^^^^^^^^^^
  File "/usr/local/lib/python3.12/zipfile/__init__.py", line 1349, in __init__
    self._RealGetContents()
  File "/usr/local/lib/python3.12/zipfile/__init__.py", line 1416, in _RealGetContents
    raise BadZipFile("File is not a zip file")
zipfile.BadZipFile: File is not a zip file
[2024-11-23T10:45:52.892+0000] {local_task_job_runner.py:266} INFO - Task exited with return code 1
[2024-11-23T10:45:52.921+0000] {taskinstance.py:3895} INFO - 0 downstream tasks scheduled from follow-on schedule check
[2024-11-23T10:45:53.561+0000] {local_task_job_runner.py:245} INFO - ::endgroup::
