[2024-11-23T10:48:25.354+0000] {local_task_job_runner.py:123} INFO - ::group::Pre task execution logs
[2024-11-23T10:48:25.377+0000] {taskinstance.py:2613} INFO - Dependencies all met for dep_context=non-requeueable deps ti=<TaskInstance: data_processing_dag.process_data manual__2024-11-23T10:48:16.443157+00:00 [queued]>
[2024-11-23T10:48:25.386+0000] {taskinstance.py:2613} INFO - Dependencies all met for dep_context=requeueable deps ti=<TaskInstance: data_processing_dag.process_data manual__2024-11-23T10:48:16.443157+00:00 [queued]>
[2024-11-23T10:48:25.387+0000] {taskinstance.py:2866} INFO - Starting attempt 1 of 1
[2024-11-23T10:48:25.462+0000] {taskinstance.py:2889} INFO - Executing <Task(PythonOperator): process_data> on 2024-11-23 10:48:16.443157+00:00
[2024-11-23T10:48:25.472+0000] {warnings.py:112} WARNING - /home/***/.local/lib/python3.12/site-packages/***/task/task_runner/standard_task_runner.py:70: DeprecationWarning: This process (pid=168) is multi-threaded, use of fork() may lead to deadlocks in the child.
  pid = os.fork()

[2024-11-23T10:48:25.476+0000] {standard_task_runner.py:72} INFO - Started process 177 to run task
[2024-11-23T10:48:25.475+0000] {standard_task_runner.py:104} INFO - Running: ['***', 'tasks', 'run', 'data_processing_dag', 'process_data', 'manual__2024-11-23T10:48:16.443157+00:00', '--job-id', '14', '--raw', '--subdir', 'DAGS_FOLDER/data_processing_dag.py', '--cfg-path', '/tmp/tmpdmgo5s4f']
[2024-11-23T10:48:25.478+0000] {standard_task_runner.py:105} INFO - Job 14: Subtask process_data
[2024-11-23T10:48:25.572+0000] {task_command.py:467} INFO - Running <TaskInstance: data_processing_dag.process_data manual__2024-11-23T10:48:16.443157+00:00 [running]> on host 8f56532c35d7
[2024-11-23T10:48:25.728+0000] {taskinstance.py:3132} INFO - Exporting env vars: AIRFLOW_CTX_DAG_OWNER='***' AIRFLOW_CTX_DAG_ID='data_processing_dag' AIRFLOW_CTX_TASK_ID='process_data' AIRFLOW_CTX_EXECUTION_DATE='2024-11-23T10:48:16.443157+00:00' AIRFLOW_CTX_TRY_NUMBER='1' AIRFLOW_CTX_DAG_RUN_ID='manual__2024-11-23T10:48:16.443157+00:00'
[2024-11-23T10:48:25.729+0000] {logging_mixin.py:190} INFO - Task instance is in running state
[2024-11-23T10:48:25.730+0000] {logging_mixin.py:190} INFO -  Previous state of the Task instance: queued
[2024-11-23T10:48:25.731+0000] {logging_mixin.py:190} INFO - Current task name:process_data state:running start_date:2024-11-23 10:48:25.378538+00:00
[2024-11-23T10:48:25.731+0000] {logging_mixin.py:190} INFO - Dag name:data_processing_dag and current dag run status:running
[2024-11-23T10:48:25.732+0000] {taskinstance.py:731} INFO - ::endgroup::
[2024-11-23T10:48:30.060+0000] {warnings.py:112} WARNING - /home/***/.local/lib/python3.12/site-packages/gdown/download.py:33: MarkupResemblesLocatorWarning: The input looks more like a filename than markup. You may want to open this file and pass the filehandle into Beautiful Soup.
  soup = bs4.BeautifulSoup(line, features="html.parser")

[2024-11-23T10:48:30.928+0000] {taskinstance.py:3311} ERROR - Task failed with exception
Traceback (most recent call last):
  File "/home/airflow/.local/lib/python3.12/site-packages/gdown/download.py", line 267, in download
    url = get_url_from_gdrive_confirmation(res.text)
          ^^^^^^^^^^^^^^^^^^^^^^^^^^^^^^^^^^^^^^^^^^
  File "/home/airflow/.local/lib/python3.12/site-packages/gdown/download.py", line 55, in get_url_from_gdrive_confirmation
    raise FileURLRetrievalError(
gdown.exceptions.FileURLRetrievalError: Cannot retrieve the public link of the file. You may need to change the permission to 'Anyone with the link', or have had many accesses. Check FAQ in https://github.com/wkentaro/gdown?tab=readme-ov-file#faq.

During handling of the above exception, another exception occurred:

Traceback (most recent call last):
  File "/home/airflow/.local/lib/python3.12/site-packages/airflow/models/taskinstance.py", line 767, in _execute_task
    result = _execute_callable(context=context, **execute_callable_kwargs)
             ^^^^^^^^^^^^^^^^^^^^^^^^^^^^^^^^^^^^^^^^^^^^^^^^^^^^^^^^^^^^^
  File "/home/airflow/.local/lib/python3.12/site-packages/airflow/models/taskinstance.py", line 733, in _execute_callable
    return ExecutionCallableRunner(
           ^^^^^^^^^^^^^^^^^^^^^^^^
  File "/home/airflow/.local/lib/python3.12/site-packages/airflow/utils/operator_helpers.py", line 252, in run
    return self.func(*args, **kwargs)
           ^^^^^^^^^^^^^^^^^^^^^^^^^^
  File "/home/airflow/.local/lib/python3.12/site-packages/airflow/models/baseoperator.py", line 417, in wrapper
    return func(self, *args, **kwargs)
           ^^^^^^^^^^^^^^^^^^^^^^^^^^^
  File "/home/airflow/.local/lib/python3.12/site-packages/airflow/operators/python.py", line 238, in execute
    return_value = self.execute_callable()
                   ^^^^^^^^^^^^^^^^^^^^^^^
  File "/home/airflow/.local/lib/python3.12/site-packages/airflow/operators/python.py", line 256, in execute_callable
    return runner.run(*self.op_args, **self.op_kwargs)
           ^^^^^^^^^^^^^^^^^^^^^^^^^^^^^^^^^^^^^^^^^^^
  File "/home/airflow/.local/lib/python3.12/site-packages/airflow/utils/operator_helpers.py", line 252, in run
    return self.func(*args, **kwargs)
           ^^^^^^^^^^^^^^^^^^^^^^^^^^
  File "/opt/airflow/dags/data_processing_dag.py", line 21, in process_data
    gdown.download(gdrive_download_url, dataset_zip_path, quiet=False)
  File "/home/airflow/.local/lib/python3.12/site-packages/gdown/download.py", line 278, in download
    raise FileURLRetrievalError(message)
gdown.exceptions.FileURLRetrievalError: Failed to retrieve file url:

	Cannot retrieve the public link of the file. You may need to change
	the permission to 'Anyone with the link', or have had many accesses.
	Check FAQ in https://github.com/wkentaro/gdown?tab=readme-ov-file#faq.

You may still be able to access the file from the browser:

	https://drive.google.com/uc?id=1jF_BovhtYn67ctVjByaqFY6NyLtF0CH5

but Gdown can't. Please check connections and permissions.
[2024-11-23T10:48:30.947+0000] {logging_mixin.py:190} INFO - Task instance in failure state
[2024-11-23T10:48:30.948+0000] {logging_mixin.py:190} INFO - Task start:2024-11-23 10:48:25.378538+00:00 end:2024-11-23 10:48:30.947185+00:00 duration:5.568647
[2024-11-23T10:48:30.949+0000] {logging_mixin.py:190} INFO - Task:<Task(PythonOperator): process_data> dag:<DAG: data_processing_dag> dagrun:<DagRun data_processing_dag @ 2024-11-23 10:48:16.443157+00:00: manual__2024-11-23T10:48:16.443157+00:00, state:running, queued_at: 2024-11-23 10:48:16.465865+00:00. externally triggered: True>
[2024-11-23T10:48:30.949+0000] {logging_mixin.py:190} INFO - Failure caused by Failed to retrieve file url:

	Cannot retrieve the public link of the file. You may need to change
	the permission to 'Anyone with the link', or have had many accesses.
	Check FAQ in https://github.com/wkentaro/gdown?tab=readme-ov-file#faq.

You may still be able to access the file from the browser:

	https://drive.google.com/uc?id=1jF_BovhtYn67ctVjByaqFY6NyLtF0CH5

but Gdown can't. Please check connections and permissions.
[2024-11-23T10:48:30.950+0000] {taskinstance.py:1225} INFO - Marking task as FAILED. dag_id=data_processing_dag, task_id=process_data, run_id=manual__2024-11-23T10:48:16.443157+00:00, execution_date=20241123T104816, start_date=20241123T104825, end_date=20241123T104830
[2024-11-23T10:48:31.062+0000] {taskinstance.py:340} INFO - ::group::Post task execution logs
[2024-11-23T10:48:31.063+0000] {standard_task_runner.py:124} ERROR - Failed to execute job 14 for task process_data (Failed to retrieve file url:

	Cannot retrieve the public link of the file. You may need to change
	the permission to 'Anyone with the link', or have had many accesses.
	Check FAQ in https://github.com/wkentaro/gdown?tab=readme-ov-file#faq.

You may still be able to access the file from the browser:

	https://drive.google.com/uc?id=1jF_BovhtYn67ctVjByaqFY6NyLtF0CH5

but Gdown can't. Please check connections and permissions.; 177)
Traceback (most recent call last):
  File "/home/airflow/.local/lib/python3.12/site-packages/gdown/download.py", line 267, in download
    url = get_url_from_gdrive_confirmation(res.text)
          ^^^^^^^^^^^^^^^^^^^^^^^^^^^^^^^^^^^^^^^^^^
  File "/home/airflow/.local/lib/python3.12/site-packages/gdown/download.py", line 55, in get_url_from_gdrive_confirmation
    raise FileURLRetrievalError(
gdown.exceptions.FileURLRetrievalError: Cannot retrieve the public link of the file. You may need to change the permission to 'Anyone with the link', or have had many accesses. Check FAQ in https://github.com/wkentaro/gdown?tab=readme-ov-file#faq.

During handling of the above exception, another exception occurred:

Traceback (most recent call last):
  File "/home/airflow/.local/lib/python3.12/site-packages/airflow/task/task_runner/standard_task_runner.py", line 117, in _start_by_fork
    ret = args.func(args, dag=self.dag)
          ^^^^^^^^^^^^^^^^^^^^^^^^^^^^^
  File "/home/airflow/.local/lib/python3.12/site-packages/airflow/cli/cli_config.py", line 49, in command
    return func(*args, **kwargs)
           ^^^^^^^^^^^^^^^^^^^^^
  File "/home/airflow/.local/lib/python3.12/site-packages/airflow/utils/cli.py", line 116, in wrapper
    return f(*args, **kwargs)
           ^^^^^^^^^^^^^^^^^^
  File "/home/airflow/.local/lib/python3.12/site-packages/airflow/cli/commands/task_command.py", line 483, in task_run
    task_return_code = _run_task_by_selected_method(args, _dag, ti)
                       ^^^^^^^^^^^^^^^^^^^^^^^^^^^^^^^^^^^^^^^^^^^^
  File "/home/airflow/.local/lib/python3.12/site-packages/airflow/cli/commands/task_command.py", line 256, in _run_task_by_selected_method
    return _run_raw_task(args, ti)
           ^^^^^^^^^^^^^^^^^^^^^^^
  File "/home/airflow/.local/lib/python3.12/site-packages/airflow/cli/commands/task_command.py", line 341, in _run_raw_task
    return ti._run_raw_task(
           ^^^^^^^^^^^^^^^^^
  File "/home/airflow/.local/lib/python3.12/site-packages/airflow/utils/session.py", line 97, in wrapper
    return func(*args, session=session, **kwargs)
           ^^^^^^^^^^^^^^^^^^^^^^^^^^^^^^^^^^^^^^
  File "/home/airflow/.local/lib/python3.12/site-packages/airflow/models/taskinstance.py", line 3005, in _run_raw_task
    return _run_raw_task(
           ^^^^^^^^^^^^^^
  File "/home/airflow/.local/lib/python3.12/site-packages/airflow/models/taskinstance.py", line 273, in _run_raw_task
    TaskInstance._execute_task_with_callbacks(
  File "/home/airflow/.local/lib/python3.12/site-packages/airflow/models/taskinstance.py", line 3159, in _execute_task_with_callbacks
    result = self._execute_task(context, task_orig)
             ^^^^^^^^^^^^^^^^^^^^^^^^^^^^^^^^^^^^^^
  File "/home/airflow/.local/lib/python3.12/site-packages/airflow/models/taskinstance.py", line 3183, in _execute_task
    return _execute_task(self, context, task_orig)
           ^^^^^^^^^^^^^^^^^^^^^^^^^^^^^^^^^^^^^^^
  File "/home/airflow/.local/lib/python3.12/site-packages/airflow/models/taskinstance.py", line 767, in _execute_task
    result = _execute_callable(context=context, **execute_callable_kwargs)
             ^^^^^^^^^^^^^^^^^^^^^^^^^^^^^^^^^^^^^^^^^^^^^^^^^^^^^^^^^^^^^
  File "/home/airflow/.local/lib/python3.12/site-packages/airflow/models/taskinstance.py", line 733, in _execute_callable
    return ExecutionCallableRunner(
           ^^^^^^^^^^^^^^^^^^^^^^^^
  File "/home/airflow/.local/lib/python3.12/site-packages/airflow/utils/operator_helpers.py", line 252, in run
    return self.func(*args, **kwargs)
           ^^^^^^^^^^^^^^^^^^^^^^^^^^
  File "/home/airflow/.local/lib/python3.12/site-packages/airflow/models/baseoperator.py", line 417, in wrapper
    return func(self, *args, **kwargs)
           ^^^^^^^^^^^^^^^^^^^^^^^^^^^
  File "/home/airflow/.local/lib/python3.12/site-packages/airflow/operators/python.py", line 238, in execute
    return_value = self.execute_callable()
                   ^^^^^^^^^^^^^^^^^^^^^^^
  File "/home/airflow/.local/lib/python3.12/site-packages/airflow/operators/python.py", line 256, in execute_callable
    return runner.run(*self.op_args, **self.op_kwargs)
           ^^^^^^^^^^^^^^^^^^^^^^^^^^^^^^^^^^^^^^^^^^^
  File "/home/airflow/.local/lib/python3.12/site-packages/airflow/utils/operator_helpers.py", line 252, in run
    return self.func(*args, **kwargs)
           ^^^^^^^^^^^^^^^^^^^^^^^^^^
  File "/opt/airflow/dags/data_processing_dag.py", line 21, in process_data
    gdown.download(gdrive_download_url, dataset_zip_path, quiet=False)
  File "/home/airflow/.local/lib/python3.12/site-packages/gdown/download.py", line 278, in download
    raise FileURLRetrievalError(message)
gdown.exceptions.FileURLRetrievalError: Failed to retrieve file url:

	Cannot retrieve the public link of the file. You may need to change
	the permission to 'Anyone with the link', or have had many accesses.
	Check FAQ in https://github.com/wkentaro/gdown?tab=readme-ov-file#faq.

You may still be able to access the file from the browser:

	https://drive.google.com/uc?id=1jF_BovhtYn67ctVjByaqFY6NyLtF0CH5

but Gdown can't. Please check connections and permissions.
[2024-11-23T10:48:31.122+0000] {local_task_job_runner.py:266} INFO - Task exited with return code 1
[2024-11-23T10:48:31.145+0000] {taskinstance.py:3895} INFO - 0 downstream tasks scheduled from follow-on schedule check
[2024-11-23T10:48:31.195+0000] {local_task_job_runner.py:245} INFO - ::endgroup::
