[2024-11-19T18:12:07.711+0000] {local_task_job_runner.py:123} INFO - ::group::Pre task execution logs
[2024-11-19T18:12:07.741+0000] {taskinstance.py:2613} INFO - Dependencies all met for dep_context=non-requeueable deps ti=<TaskInstance: upload_to_google_sheets_dag.split_data manual__2024-11-19T18:06:04.630116+00:00 [queued]>
[2024-11-19T18:12:07.757+0000] {taskinstance.py:2613} INFO - Dependencies all met for dep_context=requeueable deps ti=<TaskInstance: upload_to_google_sheets_dag.split_data manual__2024-11-19T18:06:04.630116+00:00 [queued]>
[2024-11-19T18:12:07.758+0000] {taskinstance.py:2866} INFO - Starting attempt 1 of 2
[2024-11-19T18:12:07.916+0000] {taskinstance.py:2889} INFO - Executing <Task(PythonOperator): split_data> on 2024-11-19 18:06:04.630116+00:00
[2024-11-19T18:12:07.928+0000] {standard_task_runner.py:104} INFO - Running: ['***', 'tasks', 'run', 'upload_to_google_sheets_dag', 'split_data', 'manual__2024-11-19T18:06:04.630116+00:00', '--job-id', '21', '--raw', '--subdir', 'DAGS_FOLDER/Zad3.py', '--cfg-path', '/tmp/tmpjqit6fwy']
[2024-11-19T18:12:07.926+0000] {warnings.py:112} WARNING - /home/***/.local/lib/python3.12/site-packages/***/task/task_runner/standard_task_runner.py:70: DeprecationWarning: This process (pid=196) is multi-threaded, use of fork() may lead to deadlocks in the child.
  pid = os.fork()

[2024-11-19T18:12:07.930+0000] {standard_task_runner.py:105} INFO - Job 21: Subtask split_data
[2024-11-19T18:12:07.930+0000] {standard_task_runner.py:72} INFO - Started process 205 to run task
[2024-11-19T18:12:08.134+0000] {task_command.py:467} INFO - Running <TaskInstance: upload_to_google_sheets_dag.split_data manual__2024-11-19T18:06:04.630116+00:00 [running]> on host 5dfac9e274c2
[2024-11-19T18:12:09.194+0000] {taskinstance.py:3132} INFO - Exporting env vars: AIRFLOW_CTX_DAG_OWNER='***' AIRFLOW_CTX_DAG_ID='upload_to_google_sheets_dag' AIRFLOW_CTX_TASK_ID='split_data' AIRFLOW_CTX_EXECUTION_DATE='2024-11-19T18:06:04.630116+00:00' AIRFLOW_CTX_TRY_NUMBER='1' AIRFLOW_CTX_DAG_RUN_ID='manual__2024-11-19T18:06:04.630116+00:00'
[2024-11-19T18:12:09.196+0000] {logging_mixin.py:190} INFO - Task instance is in running state
[2024-11-19T18:12:09.196+0000] {logging_mixin.py:190} INFO -  Previous state of the Task instance: queued
[2024-11-19T18:12:09.197+0000] {logging_mixin.py:190} INFO - Current task name:split_data state:running start_date:2024-11-19 18:12:07.744057+00:00
[2024-11-19T18:12:09.197+0000] {logging_mixin.py:190} INFO - Dag name:upload_to_google_sheets_dag and current dag run status:running
[2024-11-19T18:12:09.198+0000] {taskinstance.py:731} INFO - ::endgroup::
[2024-11-19T18:12:09.199+0000] {taskinstance.py:3311} ERROR - Task failed with exception
Traceback (most recent call last):
  File "/home/airflow/.local/lib/python3.12/site-packages/airflow/models/taskinstance.py", line 767, in _execute_task
    result = _execute_callable(context=context, **execute_callable_kwargs)
             ^^^^^^^^^^^^^^^^^^^^^^^^^^^^^^^^^^^^^^^^^^^^^^^^^^^^^^^^^^^^^
  File "/home/airflow/.local/lib/python3.12/site-packages/airflow/models/taskinstance.py", line 733, in _execute_callable
    return ExecutionCallableRunner(
           ^^^^^^^^^^^^^^^^^^^^^^^^
  File "/home/airflow/.local/lib/python3.12/site-packages/airflow/utils/operator_helpers.py", line 252, in run
    return self.func(*args, **kwargs)
           ^^^^^^^^^^^^^^^^^^^^^^^^^^
  File "/home/airflow/.local/lib/python3.12/site-packages/airflow/models/baseoperator.py", line 417, in wrapper
    return func(self, *args, **kwargs)
           ^^^^^^^^^^^^^^^^^^^^^^^^^^^
  File "/home/airflow/.local/lib/python3.12/site-packages/airflow/operators/python.py", line 238, in execute
    return_value = self.execute_callable()
                   ^^^^^^^^^^^^^^^^^^^^^^^
  File "/home/airflow/.local/lib/python3.12/site-packages/airflow/operators/python.py", line 256, in execute_callable
    return runner.run(*self.op_args, **self.op_kwargs)
           ^^^^^^^^^^^^^^^^^^^^^^^^^^^^^^^^^^^^^^^^^^^
  File "/home/airflow/.local/lib/python3.12/site-packages/airflow/utils/operator_helpers.py", line 252, in run
    return self.func(*args, **kwargs)
           ^^^^^^^^^^^^^^^^^^^^^^^^^^
  File "/opt/airflow/dags/Zad3.py", line 91, in split_data_task
    data = pd.DataFrame.from_dict(data_dict)
           ^^^^^^^^^^^^^^^^^^^^^^^^^^^^^^^^^
  File "/home/airflow/.local/lib/python3.12/site-packages/pandas/core/frame.py", line 1813, in from_dict
    return cls(data, index=index, columns=columns, dtype=dtype)
           ^^^^^^^^^^^^^^^^^^^^^^^^^^^^^^^^^^^^^^^^^^^^^^^^^^^^
  File "/home/airflow/.local/lib/python3.12/site-packages/pandas/core/frame.py", line 841, in __init__
    raise ValueError("DataFrame constructor not properly called!")
ValueError: DataFrame constructor not properly called!
[2024-11-19T18:12:09.224+0000] {logging_mixin.py:190} INFO - Task instance in failure state
[2024-11-19T18:12:09.225+0000] {logging_mixin.py:190} INFO - Task start:2024-11-19 18:12:07.744057+00:00 end:2024-11-19 18:12:09.223581+00:00 duration:1.479524
[2024-11-19T18:12:09.226+0000] {logging_mixin.py:190} INFO - Task:<Task(PythonOperator): split_data> dag:<DAG: upload_to_google_sheets_dag> dagrun:<DagRun upload_to_google_sheets_dag @ 2024-11-19 18:06:04.630116+00:00: manual__2024-11-19T18:06:04.630116+00:00, state:running, queued_at: 2024-11-19 18:06:05.039514+00:00. externally triggered: True>
[2024-11-19T18:12:09.227+0000] {logging_mixin.py:190} INFO - Failure caused by DataFrame constructor not properly called!
[2024-11-19T18:12:09.229+0000] {taskinstance.py:1225} INFO - Marking task as UP_FOR_RETRY. dag_id=upload_to_google_sheets_dag, task_id=split_data, run_id=manual__2024-11-19T18:06:04.630116+00:00, execution_date=20241119T180604, start_date=20241119T181207, end_date=20241119T181209
[2024-11-19T18:12:09.360+0000] {taskinstance.py:340} INFO - ::group::Post task execution logs
[2024-11-19T18:12:09.361+0000] {standard_task_runner.py:124} ERROR - Failed to execute job 21 for task split_data (DataFrame constructor not properly called!; 205)
Traceback (most recent call last):
  File "/home/airflow/.local/lib/python3.12/site-packages/airflow/task/task_runner/standard_task_runner.py", line 117, in _start_by_fork
    ret = args.func(args, dag=self.dag)
          ^^^^^^^^^^^^^^^^^^^^^^^^^^^^^
  File "/home/airflow/.local/lib/python3.12/site-packages/airflow/cli/cli_config.py", line 49, in command
    return func(*args, **kwargs)
           ^^^^^^^^^^^^^^^^^^^^^
  File "/home/airflow/.local/lib/python3.12/site-packages/airflow/utils/cli.py", line 116, in wrapper
    return f(*args, **kwargs)
           ^^^^^^^^^^^^^^^^^^
  File "/home/airflow/.local/lib/python3.12/site-packages/airflow/cli/commands/task_command.py", line 483, in task_run
    task_return_code = _run_task_by_selected_method(args, _dag, ti)
                       ^^^^^^^^^^^^^^^^^^^^^^^^^^^^^^^^^^^^^^^^^^^^
  File "/home/airflow/.local/lib/python3.12/site-packages/airflow/cli/commands/task_command.py", line 256, in _run_task_by_selected_method
    return _run_raw_task(args, ti)
           ^^^^^^^^^^^^^^^^^^^^^^^
  File "/home/airflow/.local/lib/python3.12/site-packages/airflow/cli/commands/task_command.py", line 341, in _run_raw_task
    return ti._run_raw_task(
           ^^^^^^^^^^^^^^^^^
  File "/home/airflow/.local/lib/python3.12/site-packages/airflow/utils/session.py", line 97, in wrapper
    return func(*args, session=session, **kwargs)
           ^^^^^^^^^^^^^^^^^^^^^^^^^^^^^^^^^^^^^^
  File "/home/airflow/.local/lib/python3.12/site-packages/airflow/models/taskinstance.py", line 3005, in _run_raw_task
    return _run_raw_task(
           ^^^^^^^^^^^^^^
  File "/home/airflow/.local/lib/python3.12/site-packages/airflow/models/taskinstance.py", line 273, in _run_raw_task
    TaskInstance._execute_task_with_callbacks(
  File "/home/airflow/.local/lib/python3.12/site-packages/airflow/models/taskinstance.py", line 3159, in _execute_task_with_callbacks
    result = self._execute_task(context, task_orig)
             ^^^^^^^^^^^^^^^^^^^^^^^^^^^^^^^^^^^^^^
  File "/home/airflow/.local/lib/python3.12/site-packages/airflow/models/taskinstance.py", line 3183, in _execute_task
    return _execute_task(self, context, task_orig)
           ^^^^^^^^^^^^^^^^^^^^^^^^^^^^^^^^^^^^^^^
  File "/home/airflow/.local/lib/python3.12/site-packages/airflow/models/taskinstance.py", line 767, in _execute_task
    result = _execute_callable(context=context, **execute_callable_kwargs)
             ^^^^^^^^^^^^^^^^^^^^^^^^^^^^^^^^^^^^^^^^^^^^^^^^^^^^^^^^^^^^^
  File "/home/airflow/.local/lib/python3.12/site-packages/airflow/models/taskinstance.py", line 733, in _execute_callable
    return ExecutionCallableRunner(
           ^^^^^^^^^^^^^^^^^^^^^^^^
  File "/home/airflow/.local/lib/python3.12/site-packages/airflow/utils/operator_helpers.py", line 252, in run
    return self.func(*args, **kwargs)
           ^^^^^^^^^^^^^^^^^^^^^^^^^^
  File "/home/airflow/.local/lib/python3.12/site-packages/airflow/models/baseoperator.py", line 417, in wrapper
    return func(self, *args, **kwargs)
           ^^^^^^^^^^^^^^^^^^^^^^^^^^^
  File "/home/airflow/.local/lib/python3.12/site-packages/airflow/operators/python.py", line 238, in execute
    return_value = self.execute_callable()
                   ^^^^^^^^^^^^^^^^^^^^^^^
  File "/home/airflow/.local/lib/python3.12/site-packages/airflow/operators/python.py", line 256, in execute_callable
    return runner.run(*self.op_args, **self.op_kwargs)
           ^^^^^^^^^^^^^^^^^^^^^^^^^^^^^^^^^^^^^^^^^^^
  File "/home/airflow/.local/lib/python3.12/site-packages/airflow/utils/operator_helpers.py", line 252, in run
    return self.func(*args, **kwargs)
           ^^^^^^^^^^^^^^^^^^^^^^^^^^
  File "/opt/airflow/dags/Zad3.py", line 91, in split_data_task
    data = pd.DataFrame.from_dict(data_dict)
           ^^^^^^^^^^^^^^^^^^^^^^^^^^^^^^^^^
  File "/home/airflow/.local/lib/python3.12/site-packages/pandas/core/frame.py", line 1813, in from_dict
    return cls(data, index=index, columns=columns, dtype=dtype)
           ^^^^^^^^^^^^^^^^^^^^^^^^^^^^^^^^^^^^^^^^^^^^^^^^^^^^
  File "/home/airflow/.local/lib/python3.12/site-packages/pandas/core/frame.py", line 841, in __init__
    raise ValueError("DataFrame constructor not properly called!")
ValueError: DataFrame constructor not properly called!
[2024-11-19T18:12:09.390+0000] {local_task_job_runner.py:266} INFO - Task exited with return code 1
[2024-11-19T18:12:09.418+0000] {taskinstance.py:3895} INFO - 0 downstream tasks scheduled from follow-on schedule check
[2024-11-19T18:12:09.470+0000] {local_task_job_runner.py:245} INFO - ::endgroup::
