[2024-11-23T10:51:58.420+0000] {local_task_job_runner.py:123} INFO - ::group::Pre task execution logs
[2024-11-23T10:51:58.443+0000] {taskinstance.py:2613} INFO - Dependencies all met for dep_context=non-requeueable deps ti=<TaskInstance: data_processing_dag.process_data manual__2024-11-23T10:51:51.777586+00:00 [queued]>
[2024-11-23T10:51:58.452+0000] {taskinstance.py:2613} INFO - Dependencies all met for dep_context=requeueable deps ti=<TaskInstance: data_processing_dag.process_data manual__2024-11-23T10:51:51.777586+00:00 [queued]>
[2024-11-23T10:51:58.453+0000] {taskinstance.py:2866} INFO - Starting attempt 1 of 1
[2024-11-23T10:51:58.496+0000] {taskinstance.py:2889} INFO - Executing <Task(PythonOperator): process_data> on 2024-11-23 10:51:51.777586+00:00
[2024-11-23T10:51:58.505+0000] {warnings.py:112} WARNING - /home/***/.local/lib/python3.12/site-packages/***/task/task_runner/standard_task_runner.py:70: DeprecationWarning: This process (pid=251) is multi-threaded, use of fork() may lead to deadlocks in the child.
  pid = os.fork()

[2024-11-23T10:51:58.507+0000] {standard_task_runner.py:72} INFO - Started process 260 to run task
[2024-11-23T10:51:58.507+0000] {standard_task_runner.py:104} INFO - Running: ['***', 'tasks', 'run', 'data_processing_dag', 'process_data', 'manual__2024-11-23T10:51:51.777586+00:00', '--job-id', '17', '--raw', '--subdir', 'DAGS_FOLDER/data_processing_dag.py', '--cfg-path', '/tmp/tmp6bjujnf2']
[2024-11-23T10:51:58.509+0000] {standard_task_runner.py:105} INFO - Job 17: Subtask process_data
[2024-11-23T10:51:58.607+0000] {task_command.py:467} INFO - Running <TaskInstance: data_processing_dag.process_data manual__2024-11-23T10:51:51.777586+00:00 [running]> on host 8f56532c35d7
[2024-11-23T10:51:58.799+0000] {taskinstance.py:3132} INFO - Exporting env vars: AIRFLOW_CTX_DAG_OWNER='***' AIRFLOW_CTX_DAG_ID='data_processing_dag' AIRFLOW_CTX_TASK_ID='process_data' AIRFLOW_CTX_EXECUTION_DATE='2024-11-23T10:51:51.777586+00:00' AIRFLOW_CTX_TRY_NUMBER='1' AIRFLOW_CTX_DAG_RUN_ID='manual__2024-11-23T10:51:51.777586+00:00'
[2024-11-23T10:51:58.803+0000] {logging_mixin.py:190} INFO - Task instance is in running state
[2024-11-23T10:51:58.804+0000] {logging_mixin.py:190} INFO -  Previous state of the Task instance: queued
[2024-11-23T10:51:58.805+0000] {logging_mixin.py:190} INFO - Current task name:process_data state:running start_date:2024-11-23 10:51:58.443824+00:00
[2024-11-23T10:51:58.806+0000] {logging_mixin.py:190} INFO - Dag name:data_processing_dag and current dag run status:running
[2024-11-23T10:51:58.807+0000] {taskinstance.py:731} INFO - ::endgroup::
[2024-11-23T10:51:59.459+0000] {logging_mixin.py:190} WARNING - Downloading...
[2024-11-23T10:51:59.460+0000] {logging_mixin.py:190} WARNING - From: https://drive.google.com/drive/folders/1jF_BovhtYn67ctVjByaqFY6NyLtF0CH5?usp=sharing
[2024-11-23T10:51:59.460+0000] {logging_mixin.py:190} WARNING - To: /tmp/ASIdataset.zip
[2024-11-23T10:51:59.462+0000] {logging_mixin.py:190} WARNING - 0.00B [00:00, ?B/s]
[2024-11-23T10:51:59.564+0000] {logging_mixin.py:190} WARNING - 1.08MB [00:00, 10.7MB/s]
[2024-11-23T10:51:59.566+0000] {logging_mixin.py:190} WARNING - 1.19MB [00:00, 11.5MB/s]
[2024-11-23T10:51:59.570+0000] {taskinstance.py:3311} ERROR - Task failed with exception
Traceback (most recent call last):
  File "/home/airflow/.local/lib/python3.12/site-packages/airflow/models/taskinstance.py", line 767, in _execute_task
    result = _execute_callable(context=context, **execute_callable_kwargs)
             ^^^^^^^^^^^^^^^^^^^^^^^^^^^^^^^^^^^^^^^^^^^^^^^^^^^^^^^^^^^^^
  File "/home/airflow/.local/lib/python3.12/site-packages/airflow/models/taskinstance.py", line 733, in _execute_callable
    return ExecutionCallableRunner(
           ^^^^^^^^^^^^^^^^^^^^^^^^
  File "/home/airflow/.local/lib/python3.12/site-packages/airflow/utils/operator_helpers.py", line 252, in run
    return self.func(*args, **kwargs)
           ^^^^^^^^^^^^^^^^^^^^^^^^^^
  File "/home/airflow/.local/lib/python3.12/site-packages/airflow/models/baseoperator.py", line 417, in wrapper
    return func(self, *args, **kwargs)
           ^^^^^^^^^^^^^^^^^^^^^^^^^^^
  File "/home/airflow/.local/lib/python3.12/site-packages/airflow/operators/python.py", line 238, in execute
    return_value = self.execute_callable()
                   ^^^^^^^^^^^^^^^^^^^^^^^
  File "/home/airflow/.local/lib/python3.12/site-packages/airflow/operators/python.py", line 256, in execute_callable
    return runner.run(*self.op_args, **self.op_kwargs)
           ^^^^^^^^^^^^^^^^^^^^^^^^^^^^^^^^^^^^^^^^^^^
  File "/home/airflow/.local/lib/python3.12/site-packages/airflow/utils/operator_helpers.py", line 252, in run
    return self.func(*args, **kwargs)
           ^^^^^^^^^^^^^^^^^^^^^^^^^^
  File "/opt/airflow/dags/data_processing_dag.py", line 24, in process_data
    with zipfile.ZipFile(dataset_zip_path, 'r') as zip_ref:
         ^^^^^^^^^^^^^^^^^^^^^^^^^^^^^^^^^^^^^^
  File "/usr/local/lib/python3.12/zipfile/__init__.py", line 1349, in __init__
    self._RealGetContents()
  File "/usr/local/lib/python3.12/zipfile/__init__.py", line 1416, in _RealGetContents
    raise BadZipFile("File is not a zip file")
zipfile.BadZipFile: File is not a zip file
[2024-11-23T10:51:59.586+0000] {logging_mixin.py:190} INFO - Task instance in failure state
[2024-11-23T10:51:59.587+0000] {logging_mixin.py:190} INFO - Task start:2024-11-23 10:51:58.443824+00:00 end:2024-11-23 10:51:59.586006+00:00 duration:1.142182
[2024-11-23T10:51:59.588+0000] {logging_mixin.py:190} INFO - Task:<Task(PythonOperator): process_data> dag:<DAG: data_processing_dag> dagrun:<DagRun data_processing_dag @ 2024-11-23 10:51:51.777586+00:00: manual__2024-11-23T10:51:51.777586+00:00, state:running, queued_at: 2024-11-23 10:51:51.794224+00:00. externally triggered: True>
[2024-11-23T10:51:59.588+0000] {logging_mixin.py:190} INFO - Failure caused by File is not a zip file
[2024-11-23T10:51:59.589+0000] {taskinstance.py:1225} INFO - Marking task as FAILED. dag_id=data_processing_dag, task_id=process_data, run_id=manual__2024-11-23T10:51:51.777586+00:00, execution_date=20241123T105151, start_date=20241123T105158, end_date=20241123T105159
[2024-11-23T10:51:59.842+0000] {taskinstance.py:340} INFO - ::group::Post task execution logs
[2024-11-23T10:51:59.843+0000] {standard_task_runner.py:124} ERROR - Failed to execute job 17 for task process_data (File is not a zip file; 260)
Traceback (most recent call last):
  File "/home/airflow/.local/lib/python3.12/site-packages/airflow/task/task_runner/standard_task_runner.py", line 117, in _start_by_fork
    ret = args.func(args, dag=self.dag)
          ^^^^^^^^^^^^^^^^^^^^^^^^^^^^^
  File "/home/airflow/.local/lib/python3.12/site-packages/airflow/cli/cli_config.py", line 49, in command
    return func(*args, **kwargs)
           ^^^^^^^^^^^^^^^^^^^^^
  File "/home/airflow/.local/lib/python3.12/site-packages/airflow/utils/cli.py", line 116, in wrapper
    return f(*args, **kwargs)
           ^^^^^^^^^^^^^^^^^^
  File "/home/airflow/.local/lib/python3.12/site-packages/airflow/cli/commands/task_command.py", line 483, in task_run
    task_return_code = _run_task_by_selected_method(args, _dag, ti)
                       ^^^^^^^^^^^^^^^^^^^^^^^^^^^^^^^^^^^^^^^^^^^^
  File "/home/airflow/.local/lib/python3.12/site-packages/airflow/cli/commands/task_command.py", line 256, in _run_task_by_selected_method
    return _run_raw_task(args, ti)
           ^^^^^^^^^^^^^^^^^^^^^^^
  File "/home/airflow/.local/lib/python3.12/site-packages/airflow/cli/commands/task_command.py", line 341, in _run_raw_task
    return ti._run_raw_task(
           ^^^^^^^^^^^^^^^^^
  File "/home/airflow/.local/lib/python3.12/site-packages/airflow/utils/session.py", line 97, in wrapper
    return func(*args, session=session, **kwargs)
           ^^^^^^^^^^^^^^^^^^^^^^^^^^^^^^^^^^^^^^
  File "/home/airflow/.local/lib/python3.12/site-packages/airflow/models/taskinstance.py", line 3005, in _run_raw_task
    return _run_raw_task(
           ^^^^^^^^^^^^^^
  File "/home/airflow/.local/lib/python3.12/site-packages/airflow/models/taskinstance.py", line 273, in _run_raw_task
    TaskInstance._execute_task_with_callbacks(
  File "/home/airflow/.local/lib/python3.12/site-packages/airflow/models/taskinstance.py", line 3159, in _execute_task_with_callbacks
    result = self._execute_task(context, task_orig)
             ^^^^^^^^^^^^^^^^^^^^^^^^^^^^^^^^^^^^^^
  File "/home/airflow/.local/lib/python3.12/site-packages/airflow/models/taskinstance.py", line 3183, in _execute_task
    return _execute_task(self, context, task_orig)
           ^^^^^^^^^^^^^^^^^^^^^^^^^^^^^^^^^^^^^^^
  File "/home/airflow/.local/lib/python3.12/site-packages/airflow/models/taskinstance.py", line 767, in _execute_task
    result = _execute_callable(context=context, **execute_callable_kwargs)
             ^^^^^^^^^^^^^^^^^^^^^^^^^^^^^^^^^^^^^^^^^^^^^^^^^^^^^^^^^^^^^
  File "/home/airflow/.local/lib/python3.12/site-packages/airflow/models/taskinstance.py", line 733, in _execute_callable
    return ExecutionCallableRunner(
           ^^^^^^^^^^^^^^^^^^^^^^^^
  File "/home/airflow/.local/lib/python3.12/site-packages/airflow/utils/operator_helpers.py", line 252, in run
    return self.func(*args, **kwargs)
           ^^^^^^^^^^^^^^^^^^^^^^^^^^
  File "/home/airflow/.local/lib/python3.12/site-packages/airflow/models/baseoperator.py", line 417, in wrapper
    return func(self, *args, **kwargs)
           ^^^^^^^^^^^^^^^^^^^^^^^^^^^
  File "/home/airflow/.local/lib/python3.12/site-packages/airflow/operators/python.py", line 238, in execute
    return_value = self.execute_callable()
                   ^^^^^^^^^^^^^^^^^^^^^^^
  File "/home/airflow/.local/lib/python3.12/site-packages/airflow/operators/python.py", line 256, in execute_callable
    return runner.run(*self.op_args, **self.op_kwargs)
           ^^^^^^^^^^^^^^^^^^^^^^^^^^^^^^^^^^^^^^^^^^^
  File "/home/airflow/.local/lib/python3.12/site-packages/airflow/utils/operator_helpers.py", line 252, in run
    return self.func(*args, **kwargs)
           ^^^^^^^^^^^^^^^^^^^^^^^^^^
  File "/opt/airflow/dags/data_processing_dag.py", line 24, in process_data
    with zipfile.ZipFile(dataset_zip_path, 'r') as zip_ref:
         ^^^^^^^^^^^^^^^^^^^^^^^^^^^^^^^^^^^^^^
  File "/usr/local/lib/python3.12/zipfile/__init__.py", line 1349, in __init__
    self._RealGetContents()
  File "/usr/local/lib/python3.12/zipfile/__init__.py", line 1416, in _RealGetContents
    raise BadZipFile("File is not a zip file")
zipfile.BadZipFile: File is not a zip file
[2024-11-23T10:51:59.890+0000] {local_task_job_runner.py:266} INFO - Task exited with return code 1
[2024-11-23T10:51:59.911+0000] {taskinstance.py:3895} INFO - 0 downstream tasks scheduled from follow-on schedule check
[2024-11-23T10:51:59.953+0000] {local_task_job_runner.py:245} INFO - ::endgroup::
